Workbook

Sheet Launcher
A1: LV Preliminary Design | H1: LV Optimized Design
A3: Stage | B3: 1 | C3: 2 | D3: 3 | E3: Payload | F3: % | H3: Stage | I3: 1 | J3: 2 | K3: 3 | L3: Payload | M3: %
A4: Inert | B4: =B6/B7 -> 10942.432 | C4: =C6/C7 -> 2563.6803 | D4: =D6/D7 -> 971.89889 | E4: 2000 | F4: =E4/(E4+F6) -> 0.015133987 | H4: Inert | I4: =I5/(I7-1) -> 10401.87 | J4: =J5/(J7-1) -> 3094.4731 | K4: =K5/(K7-1) -> 931.38066 | L4: =M6*M4/(1-M4) -> 2015.7685 | M4: =I16*J16*K16 -> 0.015251488
A5: Prop | B5: =B6-B4 -> 87539.459 | C5: =C6-C4 -> 22304.019 | D5: =D6-D4 -> 5831.3934 | F5: LV(excl PL) | H5: Prop | I5: =I9-I10 -> 83214.959 | J5: =J9-J10 -> 26921.916 | K5: =K9-K10 -> 5588.2839 | M5: LV(excl PL)
A6: Total | B6: =B9-C9 -> 98481.892 | C6: =C9-D9 -> 24867.699 | D6: =D9-E9 -> 6803.2923 | E6: =E4+E5 -> 2000 | F6: =SUM(B6:D6) -> 130152.88 | H6: Total | I6: =I4+I5 -> 93616.829 | J6: =J4+J5 -> 30016.389 | K6: =K4+K5 -> 6519.6646 | L6: =L4+L5 -> 2015.7685 | M6: =F6 -> 130152.88
A7: Tot/in | B7: 9 | C7: 9.7 | D7: 7 | H7: Tot/in | I7: =B7 -> 9 | J7: =C7 -> 9.7 | K7: =D7 -> 7
A9: Initial | B9: =C9/B16 -> 132152.88 | C9: =D9/C16 -> 33670.991 | D9: =E9/D16 -> 8803.2923 | E9: =E4 -> 2000 | H9: Initial | I9: =J9/I16 -> 132168.65 | J9: =K9/J16 -> 38551.822 | K9: =L9/K16 -> 8535.4332 | L9: =L4 -> 2015.7685
A10: Final | B10: =B9/B15 -> 44613.424 | C10: =C9/C15 -> 11366.973 | D10: =D9/D15 -> 2971.8989 | H10: Final | I10: =I9/I15 -> 48953.692 | J10: =J9/J15 -> 11629.906 | K10: =K9/K15 -> 2947.1492
A12: Isp | B12: 268 | C12: 285 | D12: 320 | F12: =SUM(B12:D12) -> 873 | H12: Isp | I12: =B12 -> 268 | J12: =C12 -> 285 | K12: =D12 -> 320
A13: DeltaV | B13: =B12/$F12*$F13 -> 2854.9828 | C13: =C12/$F12*$F13 -> 3036.0825 | D13: =D12/$F12*$F13 -> 3408.9347 | F13: 9300 | H13: DeltaV | I13: =9.81*I12*LN(I9/I10) -> 2611.2127 | J13: =9.81*J12*LN(J9/J10) -> 3350.6122 | K13: =9.81*K12*LN(K9/K10) -> 3338.1869 | M13: =SUM(I13:K13) -> 9300.0118
A15: Kappa | B15: =IF(B12=0,1,EXP($F13/$F12/9.81)) -> 2.9621776 | C15: =IF(C12=0,1,EXP($F13/$F12/9.81)) -> 2.9621776 | D15: =IF(D12=0,1,EXP($F13/$F12/9.81)) -> 2.9621776 | H15: Kappa | I15: 2.699871 | J15: 3.3148868 | K15: 2.8961659
A16: Lambda | B16: =(B7/B15-1)/(B7-1) -> 0.25478817 | C16: =(C7/C15-1)/(C7-1) -> 0.26145034 | D16: =(D7/D15-1)/(D7-1) -> 0.22718773 | H16: Lambda | I16: =(I7/I15-1)/(I7-1) -> 0.29168658 | J16: =(J7/J15-1)/(J7-1) -> 0.22140155 | K16: =(K7/K15-1)/(K7-1) -> 0.23616476
A21: LV initial configuration (a) | H21: Sensitivity coefficients | N21: (DeltaV Single Stage)
A23: Stage | B23: 1 | C23: 2 | D23: 3 | E23: Payload | F23: % | H23: Stage | I23: 1 | J23: 2 | K23: 3 | L23: Payload | N23: Stage | O23: 1 | P23: 2 | Q23: 3
A24: Inert | B24: 10401.87 | C24: 3094.4731 | D24: 931.38066 | E24: =E4 -> 2000 | F24: =E24/(E24+F26) -> 0.015133987 | H24: Inert | I24: =O24 -> -0.033828522 | J24: =P24+O24 -> -0.20200514 | K24: =Q24+P24+O24 -> -0.90443463 | L24: =K24 -> -0.90443463 | N24: Inert | O24: =9.81*B32*(1/B29-1/B30) -> -0.033828522 | P24: =9.81*C32*(1/C29-1/C30) -> -0.16817662 | Q24: =9.81*D32*(1/D29-1/D30) -> -0.70242949
A25: Prop | B25: 83214.959 | C25: 26921.916 | D25: 5588.2839 | F25: LV(excl PL) | H25: Prop | I25: =O25 -> 0.019894231 | J25: =P25+O24 -> 0.038723017 | K25: =Q25+P24+O24 -> 0.16646007 | N25: Prop | O25: =9.81*B32/B29 -> 0.019894231 | P25: =9.81*C32/C29 -> 0.072551539 | Q25: =9.81*D32/D29 -> 0.36846521
A26: Total | B26: =B24+B25 -> 93616.829 | C26: =C24+C25 -> 30016.389 | D26: =D24+D25 -> 6519.6646 | E26: =E24+E25 -> 2000 | F26: =SUM(B26:D26) -> 130152.88 | H26: Total | I26: =(I24+I25*(B27-1))/B27 -> 0.013925036 | J26: =(J24+J25*(C27-1))/C27 -> 0.013905681 | K26: =(K24+K25*(D27-1))/D27 -> 0.013475109 | N26: Total | O26: =(O24+O25*(B27-1))/B27 -> 0.013925036 | P26: =(P24+P25*(C27-1))/C27 -> 0.047734203 | Q26: =(Q24+Q25*(D27-1))/D27 -> 0.21548025
A27: Tot/in | B27: =B26/B24 -> 9 | C27: =C26/C24 -> 9.7 | D27: =D26/D24 -> 7 | H27: Tot/in | I27: =(I25-I24)/B27*B24/100 -> 0.62090788 | J27: =(J25-J24)/C27*C24/100 -> 0.76796579 | K27: =(K25-K24)/D27*D24/100 -> 1.4248723 | N27: Tot/in | O27: =(O25-O24)/B27*B24/100 -> 0.62090788 | P27: =(P25-P24)/C27*C24/100 -> 0.76796579 | Q27: =(Q25-Q24)/D27*D24/100 -> 1.4248723
A29: Initial | B29: =SUM(B26:$E26) -> 132152.88 | C29: =SUM(C26:$E26) -> 38536.054 | D29: =SUM(D26:$E26) -> 8519.6646
A30: Final | B30: =B29-B25 -> 48937.924 | C30: =C29-C25 -> 11614.138 | D30: =D29-D25 -> 2931.3807
A32: Isp | B32: =B12 -> 268 | C32: =C12 -> 285 | D32: =D12 -> 320 | H32: Isp | I32: =9.81*LN(B29/B30) -> 9.745321 | J32: =9.81*LN(C29/C30) -> 11.765831 | K32: =9.81*LN(D29/D30) -> 10.466323
A33: DeltaV | B33: =9.81*B32*LN(B29/B30) -> 2611.746 | C33: =9.81*C32*LN(C29/C30) -> 3353.2618 | D33: =9.81*D32*LN(D29/D30) -> 3349.2233 | F33: =SUM(B33:D33) -> 9314.2311
A35: Kappa | B35: =B29/B30 -> 2.7004187 | C35: =C29/C30 -> 3.3180297 | D35: =D29/D30 -> 2.9063658
A36: Lambda | B36: =(B27/B35-1)/(B27-1) -> 0.29160207 | C36: =(C27/C35-1)/(C27-1) -> 0.22108295 | D36: =(D27/D35-1)/(D27-1) -> 0.23475103
B38: DeltaV nom | D38: Variazione
B39: 9300 | D39: =(F33-B39) -> 14.231123
A43: LV initial configuration (b) | H43: Sensitivity coefficients | N43: (DeltaV Single Stage)
A45: Stage | B45: 1 | C45: 2 | D45: 3 | E45: Payload | F45: % | H45: Stage | I45: 1 | J45: 2 | K45: 3 | L45: Payload | N45: Stage | O45: 1 | P45: 2 | Q45: 3
A46: Inert | B46: =B48/B49 -> 10401.87 | C46: =C48/C49 -> 3094.4731 | D46: =D48/D49 -> 931.38066 | E46: 2015.7685 | F46: =E46/(E46+F48) -> 0.015251488 | H46: Inert | I46: =O46 -> -0.033813591 | J46: =P46+O46 -> -0.20169349 | K46: =Q46+P46+O46 -> -0.89907393 | L46: =K46 -> -0.89907393 | N46: Inert | O46: =9.81*B54*(1/B51-1/B52) -> -0.033813591 | P46: =9.81*C54*(1/C51-1/C52) -> -0.1678799 | Q46: =9.81*D54*(1/D51-1/D52) -> -0.69738044
A47: Prop | B47: =B48-B46 -> 83214.959 | C47: =C48-C46 -> 26921.916 | D47: =D48-D46 -> 5588.2839 | F47: LV(excl PL) | H47: Prop | I47: =O47 -> 0.019891858 | J47: =P47+O46 -> 0.038708273 | K47: =Q47+P46+O46 -> 0.16609101 | N47: Prop | O47: =9.81*B54/B51 -> 0.019891858 | P47: =9.81*C54/C51 -> 0.072521864 | Q47: =9.81*D54/D51 -> 0.3677845
A48: Total | B48: 93616.829 | C48: 30016.389 | D48: 6519.6646 | E48: =E46+E47 -> 2015.7685 | F48: =SUM(B48:D48) -> 130152.88 | H48: Total | I48: =(I46+I47*(B49-1))/B49 -> 0.013924586 | J48: =(J46+J47*(C49-1))/C49 -> 0.013924586 | K48: =(K46+K47*(D49-1))/D49 -> 0.013924586 | N48: Total | O48: =(O46+O47*(B49-1))/B49 -> 0.013924586 | P48: =(P46+P47*(C49-1))/C49 -> 0.047738177 | Q48: =(Q46+Q47*(D49-1))/D49 -> 0.21561808
A49: Tot/in | B49: 9 | C49: 9.7 | D49: 7 | H49: Tot/in | I49: =(I47-I46)/B49*B46/100 -> 0.62070788 | J49: =(J47-J46)/C49*C46/100 -> 0.76692453 | K49: =(K47-K46)/D49*D46/100 -> 1.4172486 | N49: Tot/in | O49: =(O47-O46)/B49*B46/100 -> 0.62070788 | P49: =(P47-P46)/C49*C46/100 -> 0.76692453 | Q49: =(Q47-Q46)/D49*D46/100 -> 1.4172486
A51: Initial | B51: =SUM(B48:$E48) -> 132168.65 | C51: =SUM(C48:$E48) -> 38551.822 | D51: =SUM(D48:$E48) -> 8535.4332
A52: Final | B52: =B51-B47 -> 48953.692 | C52: =C51-C47 -> 11629.906 | D52: =D51-D47 -> 2947.1492
A54: Isp | B54: 268 | C54: 285 | D54: 320 | H54: Isp | I54: =9.81*LN(B51/B52) -> 9.743331 | J54: =9.81*LN(C51/C52) -> 11.756534 | K54: =9.81*LN(D51/D52) -> 10.431834
A55: DeltaV | B55: =9.81*B54*LN(B51/B52) -> 2611.2127 | C55: =9.81*C54*LN(C51/C52) -> 3350.6122 | D55: =9.81*D54*LN(D51/D52) -> 3338.1869 | F55: =SUM(B55:D55) -> 9300.0118
A57: Kappa | B57: =B51/B52 -> 2.699871 | C57: =C51/C52 -> 3.3148868 | D57: =D51/D52 -> 2.8961659
A58: Lambda | B58: =(B49/B57-1)/(B49-1) -> 0.29168658 | C58: =(C49/C57-1)/(C49-1) -> 0.22140155 | D58: =(D49/D57-1)/(D49-1) -> 0.23616476
B60: DeltaV nom | D60: Variazione
B61: 9300 | D61: =(F55-B61) -> 0.011844902
...

Sheet Optimization
B1: Tot/in | C1: =Launcher!B7 -> 9 | D1: =Launcher!C7 -> 9.7 | E1: =Launcher!D7 -> 7
B2: Isp | C2: =Launcher!B12 -> 268 | D2: =Launcher!C12 -> 285 | E2: =Launcher!D12 -> 320
B3: c | C3: =9.81*C2 -> 2629.08 | D3: =9.81*D2 -> 2795.85 | E3: =9.81*E2 -> 3139.2 | H3: DeltaV | I3: =Launcher!F13 -> 9300
A5: alpha | C5: Kappa 1 | D5: Kappa 2 | E5: Kappa 3 | F5: DeltaV 1 | G5: DeltaV 2 | H5: DeltaV 3 | I5: Errore
A6: 0.000543362 | C6: =C$1*($A6*C$3-1)/C$3/$A6 -> 2.699871 | D6: =D$1*($A6*D$3-1)/D$3/$A6 -> 3.3148868 | E6: =E$1*($A6*E$3-1)/E$3/$A6 -> 2.8961659 | F6: =C$3*LN(C6) -> 2611.2127 | G6: =D$3*LN(D6) -> 3350.6122 | H6: =E$3*LN(E6) -> 3338.1869 | I6: =SUM(F6:H6)-I$3 -> 0.011844902
A7: =A6+0.00001 -> 0.000553362 | C7: =C$1*($A7*C$3-1)/C$3/$A7 -> 2.8137228 | D7: =D$1*($A7*D$3-1)/D$3/$A7 -> 3.4302744 | E7: =E$1*($A7*E$3-1)/E$3/$A7 -> 2.9703278 | F7: =C$3*LN(C7) -> 2719.8055 | G7: =D$3*LN(D7) -> 3446.2773 | H7: =E$3*LN(E7) -> 3417.5601 | I7: =SUM(F7:H7)-I$3 -> 283.64284
A8: =A7+0.00001 -> 0.000563362 | C8: =C$1*($A8*C$3-1)/C$3/$A8 -> 2.9235328 | D8: =D$1*($A8*D$3-1)/D$3/$A8 -> 3.5415656 | E8: =E$1*($A8*E$3-1)/E$3/$A8 -> 3.0418568 | F8: =C$3*LN(C8) -> 2820.458 | G8: =D$3*LN(D8) -> 3535.545 | H8: =E$3*LN(E8) -> 3492.2599 | I8: =SUM(F8:H8)-I$3 -> 548.2628
A9: =A8+0.00001 -> 0.000573362 | C9: =C$1*($A9*C$3-1)/C$3/$A9 -> 3.0295124 | D9: =D$1*($A9*D$3-1)/D$3/$A9 -> 3.6489748 | E9: =E$1*($A9*E$3-1)/E$3/$A9 -> 3.1108907 | F9: =C$3*LN(C9) -> 2914.0767 | G9: =D$3*LN(D9) -> 3619.0776 | H9: =E$3*LN(E9) -> 3562.7066 | I9: =SUM(F9:H9)-I$3 -> 795.86085
A10: =A9+0.00001 -> 0.000583362 | C10: =C$1*($A10*C$3-1)/C$3/$A10 -> 3.1318586 | D10: =D$1*($A10*D$3-1)/D$3/$A10 -> 3.7527016 | E10: =E$1*($A10*E$3-1)/E$3/$A10 -> 3.1775579 | F10: =C$3*LN(C10) -> 3001.4277 | G10: =D$3*LN(D10) -> 3697.4445 | H10: =E$3*LN(E10) -> 3629.2697 | I10: =SUM(F10:H10)-I$3 -> 1028.142
A11: =A10+0.00001 -> 0.000593362 | C11: =C$1*($A11*C$3-1)/C$3/$A11 -> 3.2307551 | D11: =D$1*($A11*D$3-1)/D$3/$A11 -> 3.8529321 | E11: =E$1*($A11*E$3-1)/E$3/$A11 -> 3.2419779 | F11: =C$3*LN(C11) -> 3083.1638 | G11: =D$3*LN(D11) -> 3771.1388 | H11: =E$3*LN(E11) -> 3692.2756 | I11: =SUM(F11:H11)-I$3 -> 1246.5782
A12: =A11+0.00001 -> 0.000603362 | C12: =C$1*($A12*C$3-1)/C$3/$A12 -> 3.3263734 | D12: =D$1*($A12*D$3-1)/D$3/$A12 -> 3.9498402 | E12: =E$1*($A12*E$3-1)/E$3/$A12 -> 3.3042626 | F12: =C$3*LN(C12) -> 3159.8456 | G12: =D$3*LN(D12) -> 3840.5896 | H12: =E$3*LN(E12) -> 3752.0137 | I12: =SUM(F12:H12)-I$3 -> 1452.4489
A13: =A12+0.00001 -> 0.000613362 | C13: =C$1*($A13*C$3-1)/C$3/$A13 -> 3.4188738 | D13: =D$1*($A13*D$3-1)/D$3/$A13 -> 4.0435884 | E13: =E$1*($A13*E$3-1)/E$3/$A13 -> 3.3645164 | F13: =C$3*LN(C13) -> 3231.9575 | G13: =D$3*LN(D13) -> 3906.173 | H13: =E$3*LN(E13) -> 3808.7419 | I13: =SUM(F13:H13)-I$3 -> 1646.8724
A14: =A13+0.00001 -> 0.000623362 | C14: =C$1*($A14*C$3-1)/C$3/$A14 -> 3.5084065 | D14: =D$1*($A14*D$3-1)/D$3/$A14 -> 4.1343288 | E14: =E$1*($A14*E$3-1)/E$3/$A14 -> 3.422837 | F14: =C$3*LN(C14) -> 3299.9212 | G14: =D$3*LN(D14) -> 3968.2198 | H14: =E$3*LN(E14) -> 3862.6906 | I14: =SUM(F14:H14)-I$3 -> 1830.8316
A15: =A14+0.00001 -> 0.000633362 | C15: =C$1*($A15*C$3-1)/C$3/$A15 -> 3.5951119 | D15: =D$1*($A15*D$3-1)/D$3/$A15 -> 4.2222039 | E15: =E$1*($A15*E$3-1)/E$3/$A15 -> 3.479316 | F15: =C$3*LN(C15) -> 3364.1054 | G15: =D$3*LN(D15) -> 4027.0228 | H15: =E$3*LN(E15) -> 3914.0667 | I15: =SUM(F15:H15)-I$3 -> 2005.1948
A16: =A15+0.00001 -> 0.000643362 | C16: =C$1*($A16*C$3-1)/C$3/$A16 -> 3.679122 | D16: =D$1*($A16*D$3-1)/D$3/$A16 -> 4.3073472 | E16: =E$1*($A16*E$3-1)/E$3/$A16 -> 3.5340392 | F16: =C$3*LN(C16) -> 3424.8345 | G16: =D$3*LN(D16) -> 4082.8419 | H16: =E$3*LN(E16) -> 3963.0562 | I16: =SUM(F16:H16)-I$3 -> 2170.7326
A19: 0.0005164 | C19: =C$1*($A19*C$3-1)/C$3/$A19 -> 2.370932 | D19: =D$1*($A19*D$3-1)/D$3/$A19 -> 2.9815106 | E19: =E$1*($A19*E$3-1)/E$3/$A19 -> 2.6818988 | F19: =C$3*LN(C19) -> 2269.6404 | G19: =D$3*LN(D19) -> 3054.2707 | H19: =E$3*LN(E19) -> 3096.8994 | I19: =SUM(F19:H19)-I$3 -> -879.18952
A20: =A19+0.000001 -> 0.0005174 | C20: =C$1*($A20*C$3-1)/C$3/$A20 -> 2.3837443 | D20: =D$1*($A20*D$3-1)/D$3/$A20 -> 2.9944957 | E20: =E$1*($A20*E$3-1)/E$3/$A20 -> 2.6902445 | F20: =C$3*LN(C20) -> 2283.8094 | G20: =D$3*LN(D20) -> 3066.4208 | H20: =E$3*LN(E20) -> 3106.6531 | I20: =SUM(F20:H20)-I$3 -> -843.11675
A21: =A20+0.000001 -> 0.0005184 | C21: =C$1*($A21*C$3-1)/C$3/$A21 -> 2.3965071 | D21: =D$1*($A21*D$3-1)/D$3/$A21 -> 3.0074307 | E21: =E$1*($A21*E$3-1)/E$3/$A21 -> 2.6985581 | F21: =C$3*LN(C21) -> 2297.8483 | G21: =D$3*LN(D21) -> 3078.4717 | H21: =E$3*LN(E21) -> 3116.3391 | I21: =SUM(F21:H21)-I$3 -> -807.34098
A22: =A21+0.000001 -> 0.0005194 | C22: =C$1*($A22*C$3-1)/C$3/$A22 -> 2.4092208 | D22: =D$1*($A22*D$3-1)/D$3/$A22 -> 3.0203159 | E22: =E$1*($A22*E$3-1)/E$3/$A22 -> 2.7068397 | F22: =C$3*LN(C22) -> 2311.7589 | G22: =D$3*LN(D22) -> 3090.4248 | H22: =E$3*LN(E22) -> 3125.9582 | I22: =SUM(F22:H22)-I$3 -> -771.85815
A23: =A22+0.000001 -> 0.0005204 | C23: =C$1*($A23*C$3-1)/C$3/$A23 -> 2.4218856 | D23: =D$1*($A23*D$3-1)/D$3/$A23 -> 3.0331516 | E23: =E$1*($A23*E$3-1)/E$3/$A23 -> 2.7150894 | F23: =C$3*LN(C23) -> 2325.5433 | G23: =D$3*LN(D23) -> 3102.2814 | H23: =E$3*LN(E23) -> 3135.5111 | I23: =SUM(F23:H23)-I$3 -> -736.66429
A24: =A23+0.000001 -> 0.0005214 | C24: =C$1*($A24*C$3-1)/C$3/$A24 -> 2.4345019 | D24: =D$1*($A24*D$3-1)/D$3/$A24 -> 3.045938 | E24: =E$1*($A24*E$3-1)/E$3/$A24 -> 2.7233075 | F24: =C$3*LN(C24) -> 2339.2033 | G24: =D$3*LN(D24) -> 3114.0427 | H24: =E$3*LN(E24) -> 3144.9985 | I24: =SUM(F24:H24)-I$3 -> -701.75551
A25: =A24+0.000001 -> 0.0005224 | C25: =C$1*($A25*C$3-1)/C$3/$A25 -> 2.4470698 | D25: =D$1*($A25*D$3-1)/D$3/$A25 -> 3.0586755 | E25: =E$1*($A25*E$3-1)/E$3/$A25 -> 2.7314941 | F25: =C$3*LN(C25) -> 2352.7409 | G25: =D$3*LN(D25) -> 3125.7099 | H25: =E$3*LN(E25) -> 3154.4212 | I25: =SUM(F25:H25)-I$3 -> -667.12798
A26: =A25+0.000001 -> 0.0005234 | C26: =C$1*($A26*C$3-1)/C$3/$A26 -> 2.4595898 | D26: =D$1*($A26*D$3-1)/D$3/$A26 -> 3.0713643 | E26: =E$1*($A26*E$3-1)/E$3/$A26 -> 2.7396494 | F26: =C$3*LN(C26) -> 2366.1577 | G26: =D$3*LN(D26) -> 3137.2844 | H26: =E$3*LN(E26) -> 3163.7798 | I26: =SUM(F26:H26)-I$3 -> -632.77798
A27: =A26+0.000001 -> 0.0005244 | C27: =C$1*($A27*C$3-1)/C$3/$A27 -> 2.4720619 | D27: =D$1*($A27*D$3-1)/D$3/$A27 -> 3.0840048 | E27: =E$1*($A27*E$3-1)/E$3/$A27 -> 2.7477737 | F27: =C$3*LN(C27) -> 2379.4557 | G27: =D$3*LN(D27) -> 3148.7674 | H27: =E$3*LN(E27) -> 3173.0751 | I27: =SUM(F27:H27)-I$3 -> -598.70182
A28: =A27+0.000001 -> 0.0005254 | C28: =C$1*($A28*C$3-1)/C$3/$A28 -> 2.4844866 | D28: =D$1*($A28*D$3-1)/D$3/$A28 -> 3.0965971 | E28: =E$1*($A28*E$3-1)/E$3/$A28 -> 2.755867 | F28: =C$3*LN(C28) -> 2392.6365 | G28: =D$3*LN(D28) -> 3160.1598 | H28: =E$3*LN(E28) -> 3182.3078 | I28: =SUM(F28:H28)-I$3 -> -564.89591
A29: =A28+0.000001 -> 0.0005264 | C29: =C$1*($A29*C$3-1)/C$3/$A29 -> 2.4968641 | D29: =D$1*($A29*D$3-1)/D$3/$A29 -> 3.1091415 | E29: =E$1*($A29*E$3-1)/E$3/$A29 -> 2.7639296 | F29: =C$3*LN(C29) -> 2405.7018 | G29: =D$3*LN(D29) -> 3171.4631 | H29: =E$3*LN(E29) -> 3191.4784 | I29: =SUM(F29:H29)-I$3 -> -531.35671
A32: 0.000547 | C32: =C$1*($A32*C$3-1)/C$3/$A32 -> 2.741772 | D32: =D$1*($A32*D$3-1)/D$3/$A32 -> 3.357353 | E32: =E$1*($A32*E$3-1)/E$3/$A32 -> 2.9234598 | F32: =C$3*LN(C32) -> 2651.7017 | G32: =D$3*LN(D32) -> 3386.2018 | H32: =E$3*LN(E32) -> 3367.6326 | I32: =SUM(F32:H32)-I$3 -> 105.53609
A33: =A32+0.0000001 -> 0.0005471 | C33: =C$1*($A33*C$3-1)/C$3/$A33 -> 2.7429159 | D33: =D$1*($A33*D$3-1)/D$3/$A33 -> 3.3585123 | E33: =E$1*($A33*E$3-1)/E$3/$A33 -> 2.9242049 | F33: =C$3*LN(C33) -> 2652.7984 | G33: =D$3*LN(D33) -> 3387.167 | H33: =E$3*LN(E33) -> 3368.4326 | I33: =SUM(F33:H33)-I$3 -> 108.39801
A34: =A33+0.0000001 -> 0.0005472 | C34: =C$1*($A34*C$3-1)/C$3/$A34 -> 2.7440594 | D34: =D$1*($A34*D$3-1)/D$3/$A34 -> 3.3596712 | E34: =E$1*($A34*E$3-1)/E$3/$A34 -> 2.9249498 | F34: =C$3*LN(C34) -> 2653.8942 | G34: =D$3*LN(D34) -> 3388.1316 | H34: =E$3*LN(E34) -> 3369.2321 | I34: =SUM(F34:H34)-I$3 -> 111.25788
A35: =A34+0.0000001 -> 0.0005473 | C35: =C$1*($A35*C$3-1)/C$3/$A35 -> 2.7452024 | D35: =D$1*($A35*D$3-1)/D$3/$A35 -> 3.3608297 | E35: =E$1*($A35*E$3-1)/E$3/$A35 -> 2.9256944 | F35: =C$3*LN(C35) -> 2654.9891 | G35: =D$3*LN(D35) -> 3389.0955 | H35: =E$3*LN(E35) -> 3370.0311 | I35: =SUM(F35:H35)-I$3 -> 114.11571
A36: =A35+0.0000001 -> 0.0005474 | C36: =C$1*($A36*C$3-1)/C$3/$A36 -> 2.7463451 | D36: =D$1*($A36*D$3-1)/D$3/$A36 -> 3.3619878 | E36: =E$1*($A36*E$3-1)/E$3/$A36 -> 2.9264387 | F36: =C$3*LN(C36) -> 2656.0832 | G36: =D$3*LN(D36) -> 3390.0587 | H36: =E$3*LN(E36) -> 3370.8297 | I36: =SUM(F36:H36)-I$3 -> 116.97151
A37: =A36+0.0000001 -> 0.0005475 | C37: =C$1*($A37*C$3-1)/C$3/$A37 -> 2.7474873 | D37: =D$1*($A37*D$3-1)/D$3/$A37 -> 3.3631454 | E37: =E$1*($A37*E$3-1)/E$3/$A37 -> 2.9271827 | F37: =C$3*LN(C37) -> 2657.1764 | G37: =D$3*LN(D37) -> 3391.0212 | H37: =E$3*LN(E37) -> 3371.6277 | I37: =SUM(F37:H37)-I$3 -> 119.82528
A38: =A37+0.0000001 -> 0.0005476 | C38: =C$1*($A38*C$3-1)/C$3/$A38 -> 2.7486291 | D38: =D$1*($A38*D$3-1)/D$3/$A38 -> 3.3643026 | E38: =E$1*($A38*E$3-1)/E$3/$A38 -> 2.9279264 | F38: =C$3*LN(C38) -> 2658.2688 | G38: =D$3*LN(D38) -> 3391.9831 | H38: =E$3*LN(E38) -> 3372.4252 | I38: =SUM(F38:H38)-I$3 -> 122.67702
A39: =A38+0.0000001 -> 0.0005477 | C39: =C$1*($A39*C$3-1)/C$3/$A39 -> 2.7497705 | D39: =D$1*($A39*D$3-1)/D$3/$A39 -> 3.3654594 | E39: =E$1*($A39*E$3-1)/E$3/$A39 -> 2.9286699 | F39: =C$3*LN(C39) -> 2659.3603 | G39: =D$3*LN(D39) -> 3392.9442 | H39: =E$3*LN(E39) -> 3373.2222 | I39: =SUM(F39:H39)-I$3 -> 125.52673
A40: =A39+0.0000001 -> 0.0005478 | C40: =C$1*($A40*C$3-1)/C$3/$A40 -> 2.7509114 | D40: =D$1*($A40*D$3-1)/D$3/$A40 -> 3.3666157 | E40: =E$1*($A40*E$3-1)/E$3/$A40 -> 2.9294131 | F40: =C$3*LN(C40) -> 2660.4509 | G40: =D$3*LN(D40) -> 3393.9047 | H40: =E$3*LN(E40) -> 3374.0188 | I40: =SUM(F40:H40)-I$3 -> 128.37441
A41: =A40+0.0000001 -> 0.0005479 | C41: =C$1*($A41*C$3-1)/C$3/$A41 -> 2.752052 | D41: =D$1*($A41*D$3-1)/D$3/$A41 -> 3.3677717 | E41: =E$1*($A41*E$3-1)/E$3/$A41 -> 2.9301561 | F41: =C$3*LN(C41) -> 2661.5407 | G41: =D$3*LN(D41) -> 3394.8645 | H41: =E$3*LN(E41) -> 3374.8148 | I41: =SUM(F41:H41)-I$3 -> 131.22007
A42: =A41+0.0000001 -> 0.000548 | C42: =C$1*($A42*C$3-1)/C$3/$A42 -> 2.7531921 | D42: =D$1*($A42*D$3-1)/D$3/$A42 -> 3.3689272 | E42: =E$1*($A42*E$3-1)/E$3/$A42 -> 2.9308988 | F42: =C$3*LN(C42) -> 2662.6297 | G42: =D$3*LN(D42) -> 3395.8236 | H42: =E$3*LN(E42) -> 3375.6104 | I42: =SUM(F42:H42)-I$3 -> 134.06371
A45: 0.0005164 | C45: =C$1*($A45*C$3-1)/C$3/$A45 -> 2.370932 | D45: =D$1*($A45*D$3-1)/D$3/$A45 -> 2.9815106 | E45: =E$1*($A45*E$3-1)/E$3/$A45 -> 2.6818988 | F45: =C$3*LN(C45) -> 2269.6404 | G45: =D$3*LN(D45) -> 3054.2707 | H45: =E$3*LN(E45) -> 3096.8994 | I45: =SUM(F45:H45)-I$3 -> -879.18952
A46: =A45+0.00000001 -> 0.00051641 | C46: =C$1*($A46*C$3-1)/C$3/$A46 -> 2.3710604 | D46: =D$1*($A46*D$3-1)/D$3/$A46 -> 2.9816407 | E46: =E$1*($A46*E$3-1)/E$3/$A46 -> 2.6819824 | F46: =C$3*LN(C46) -> 2269.7827 | G46: =D$3*LN(D46) -> 3054.3927 | H46: =E$3*LN(E46) -> 3096.9973 | I46: =SUM(F46:H46)-I$3 -> -878.82731
A47: =A46+0.00000001 -> 0.00051642 | C47: =C$1*($A47*C$3-1)/C$3/$A47 -> 2.3711887 | D47: =D$1*($A47*D$3-1)/D$3/$A47 -> 2.9817708 | E47: =E$1*($A47*E$3-1)/E$3/$A47 -> 2.682066 | F47: =C$3*LN(C47) -> 2269.9251 | G47: =D$3*LN(D47) -> 3054.5147 | H47: =E$3*LN(E47) -> 3097.0951 | I47: =SUM(F47:H47)-I$3 -> -878.46513
...
